Workbook

Sheet Amendment EUR (2)
A1: !!Please insert lines under the sub-headings if necessary!! | C1: !! Pay attention not to erase formulas in the blue cells !! | H1: If this table is filled up, no need to fill in the "project budget in euros" sheet | N1: Do not fill in this table in euros - it will fill up automatically !! Pay attention not to erase formulas in the cells !! | U1: Careful : if you add extra lines, remember to copy formulas !
A2: Name of the person in charge of the budget | O2: Name of the person in charge of the budget | P2: =C2 -> 0
A3: Name of the applicant NGO | C3: Sened Organization | H3: Euro exchange rate € / USD | J3: 0.047 | K3: <If necessary update the local currency exchange rate in J3 cell | O3: Name of the applicant NGO | P3: =C3 -> Sened Organization
A4: Project title | K4: Control columns | O4: Project title | P4: =C4 -> 0 | X4: Control columns
B5: Expenditure related to the project Recommendations | C5: Unit | D5: Number of units | E5: Unit cost in EUR | F5: Total cost in EUR | H5: Year 1 in TRY | I5: Year 2 in TRY | J5: Year 3 in TRY | K5: Total 3 years in TRY | L5: Discrepancy (column F-K) must equal zero | O5: Expenditure related to the project Recommendations | P5: Unit | Q5: Number of units | R5: Unit cost (euros) | S5: Total cost (euros) | U5: Year 1 (euros) | V5: Year 2 (euros) | W5: Year 3 (euros) | X5: Total 3 years (euros) | Y5: Discrepancy (column S-X) must equal zero | AA5: Sened Contribution | AD5: 45505 | AE5: 45536 | AF5: 45566 | AG5: 45597 | AH5: 45627 | AI5: 45658 | AJ5: 45689 | AK5: TOTAL EXPENSES | AL5: % | AM5: Remaining
A6: 1 | B6: Human resources dedicated to the project | N6: 1 | O6: Human resources dedicated to the project
A7: 1.1 | B7: Salaries and employer's contributions | N7: 1.1 | O7: Salaries and employer's contributions
B8: Salary for coordination
A9: 1.1.01 | B9: IT and Media Officer (50%) TR | C9: per month | D9: 6 | E9: 1650 | AA9: =D9*E9*AD9 -> 4950 | AD9: 0.5
A10: 1.1.02 | B10: MHPSS Technical Specialist (10%) TR | C10: per month | D10: 6 | E10: 3500 | N10: 1.1.4 | O10: MHPSS Technical Specialist (5%) TR | P10: per month | Q10: 6 | R10: =E10*$J$3 -> 164.5 | S10: =R10*Q10 -> 987 | U10: =H10*$J$3 -> 0 | V10: =I10*$J$3 -> 0 | W10: =J10*$J$3 -> 0 | X10: =SUM(U10:W10) -> 0 | Y10: =S10-X10 -> 987 | Z10: =SUM(F10:F16)/F72 -> 0 | AA10: =D10*E10*AD10 -> 2100 | AD10: 0.1
A11: 1.1.03 | B11: Supply Chain Coordinator (10%) TR | C11: per month | D11: 6 | E11: 3100 | N11: 1.1.5 | O11: Supply Chain Coordinator (5%) TR | P11: per month | Q11: 6 | R11: =E11*$J$3 -> 145.7 | S11: =R11*Q11 -> 874.2 | U11: =H11*$J$3 -> 0 | V11: =I11*$J$3 -> 0 | W11: =J11*$J$3 -> 0 | X11: =SUM(U11:W11) -> 0 | Y11: =S11-X11 -> 874.2 | AA11: =D11*E11*AD11 -> 1860 | AD11: 0.1
A12: 1.1.04 | B12: Project Coordinator (10%) TR | C12: per month | D12: 6 | E12: 3100 | N12: 1.1.6 | O12: Project Coordinator (5%) TR | P12: per month | Q12: 6 | R12: =E12*$J$3 -> 145.7 | S12: =R12*Q12 -> 874.2 | U12: =H12*$J$3 -> 0 | V12: =I12*$J$3 -> 0 | W12: =J12*$J$3 -> 0 | X12: =SUM(U12:W12) -> 0 | Y12: =S12-X12 -> 874.2 | AA12: =D12*E12*AD12 -> 1860 | AD12: 0.1
A13: 1.1.05 | B13: Inclusion Technical Specialist (10%) SY | C13: per month | D13: 6 | E13: 850 | N13: 1.1.13 | O13: Inclusion Technical Specialist (5%) SY | P13: per month | Q13: 6 | R13: =E13*$J$3 -> 39.95 | S13: =R13*Q13 -> 239.7 | U13: =H13*$J$3 -> 0 | V13: =I13*$J$3 -> 0 | W13: =J13*$J$3 -> 0 | X13: =SUM(U13:W13) -> 0 | Y13: =S13-X13 -> 239.7 | AA13: =D13*E13*AD13 -> 510 | AD13: 0.1
A14: 1.1.06 | B14: MEAL Coordinator (10%) TR | C14: per month | D14: 6 | E14: 3100 | N14: 1.1.10 | O14: MEAL Coordinator (5%) TR | P14: per month | Q14: 6 | R14: =E14*$J$3 -> 145.7 | S14: =R14*Q14 -> 874.2 | U14: =H14*$J$3 -> 0 | V14: =I14*$J$3 -> 0 | W14: =J14*$J$3 -> 0 | X14: =SUM(U14:W14) -> 0 | Y14: =S14-X14 -> 874.2 | AA14: =D14*E14*AD14 -> 1860 | AD14: 0.1
A15: 1.1.07 | B15: HR Coordinator (10%) TR | C15: per month | D15: 6 | E15: 3100 | N15: 1.1.8 | O15: HR Coordinator (20%) TR | P15: per month | Q15: 6 | R15: =E15*$J$3 -> 145.7 | S15: =R15*Q15 -> 874.2 | U15: =H15*$J$3 -> 0 | V15: =I15*$J$3 -> 0 | W15: =J15*$J$3 -> 0 | X15: =SUM(U15:W15) -> 0 | Y15: =S15-X15 -> 874.2 | AA15: =D15*E15*AD15 -> 1860 | AD15: 0.1
A16: 1.1.08 | B16: Finance Coordiantor (10%) TR | C16: per month | D16: 6 | E16: 3100 | AA16: =D16*E16*AD16 -> 1860 | AD16: 0.1
B17: Salary for operational staff
A18: 1.1.08 | B18: Project Officer (100%) TR | C18: per month | D18: 5 | E18: 1650 | F18: =E18*D18 -> 8250 | N18: 1.1.11 | O18: =B18 -> Project Officer (100%) TR | P18: per month | Q18: 6 | R18: =E18*$J$3 -> 77.55 | S18: =R18*Q18 -> 465.3 | U18: =H18*$J$3 -> 0 | V18: =I18*$J$3 -> 0 | W18: =J18*$J$3 -> 0 | X18: =SUM(U18:W18) -> 0 | Y18: =S18-X18 -> 465.3 | Z18: =SUM(F18:F31)/F72 -> 0.54 | AD18: 1441.423 | AE18: 1368.7681 | AF18: 1354.1584 | AG18: 1392.9992 | AH18: 1415.5261 | AI18: 1812.287 | AJ18: 1807.6306 | AK18: =SUM(AD18:AJ18) -> 10592.792 | AL18: =AK18/F18 -> 1.2839748 | AM18: =F18-AK18 -> -2342.7925
A19: 1.1.09 | B19: Finance Assistant (100%) TR | C19: per month | D19: 5 | E19: 800 | F19: =E19*D19 -> 4000 | N19: 1.1.7 | O19: Finance Officer (20%) TR | P19: per month | Q19: 6 | R19: =E19*$J$3 -> 37.6 | S19: =R19*Q19 -> 225.6 | U19: =H19*$J$3 -> 0 | V19: =I19*$J$3 -> 0 | W19: =J19*$J$3 -> 0 | X19: =SUM(U19:W19) -> 0 | Y19: =S19-X19 -> 225.6 | AD19: 333.03423 | AE19: 1060.317 | AF19: 1048.8569 | AG19: -1.238812 | AH19: 0 | AI19: 1432.8779 | AJ19: 1429.4088 | AK19: =SUM(AD19:AJ19) -> 5303.256 | AL19: =AK19/F19 -> 1.325814 | AM19: =F19-AK19 -> -1303.256
A20: 1.1.10 | B20: Supply Assistant (100%) TR | C20: per month | D20: 5 | E20: 800 | F20: =E20*D20 -> 4000 | AD20: 0 | AE20: 1368.7681 | AF20: 1354.1584 | AG20: -0.9802656 | AH20: 0 | AI20: 1285.4684 | AJ20: 1280.4479 | AK20: =SUM(AD20:AJ20) -> 5287.8625 | AL20: =AK20/F20 -> 1.3219656 | AM20: =F20-AK20 -> -1287.8625
A21: 1.1.11 | B21: Child safeguarding specalist (15%) | C21: per month | D21: 5 | E21: 300 | F21: =E21*D21 -> 1500 | AD21: 0 | AE21: 743.45667 | AF21: 565.01871 | AG21: 329.782 | AH21: 119.86201 | AI21: 374.34356 | AJ21: 377.45982 | AK21: =SUM(AD21:AJ21) -> 2509.9228 | AL21: =AK21/F21 -> 1.6732818 | AM21: =F21-AK21 -> -1009.9228
A22: 1.1.12 | B22: Case Manager*1 (100%) - SY | C22: per month | D22: 5 | E22: 700 | F22: =E22*D22 -> 3500 | N22: 1.1.14 | O22: Case Manager*2 (100%) - SY | P22: per month | Q22: 10 | R22: =E22*$J$3 -> 32.9 | S22: =R22*Q22 -> 329 | U22: =H22*$J$3 -> 0 | V22: =I22*$J$3 -> 0 | W22: =J22*$J$3 -> 0 | X22: =SUM(U22:W22) -> 0 | Y22: =S22-X22 -> 329 | AD22: 0 | AE22: 572.34207 | AF22: 588.36843 | AG22: 607.02616 | AH22: 622.74934 | AI22: 686.61608 | AJ22: 689.31955 | AK22: =SUM(AD22:AJ22) -> 3766.4216 | AL22: =AK22/F22 -> 1.0761205 | AM22: =F22-AK22 -> -266.42162
A23: 1.1.13 | B23: Case Officer*1 ( 100%)-SY | C23: per month | D23: 5 | E23: 500 | F23: =E23*D23 -> 2500 | AD23: 0 | AE23: 136.63482 | AF23: 452.5911 | AG23: 186.77728 | AH23: 0 | AI23: 1110.6884 | AJ23: 586.3686 | AK23: =SUM(AD23:AJ23) -> 2473.0602 | AL23: =AK23/F23 -> 0.98922408 | AM23: =F23-AK23 -> 26.9398
A24: 1.1.14 | B24: PSS Officer*2 (100%) - SY | C24: per month | D24: 10 | E24: 500 | F24: =E24*D24 -> 5000 | N24: 1.1.15 | O24: PSS Officer*2 (100%) - SY | P24: per month | Q24: 10 | R24: =E24*$J$3 -> 23.5 | S24: =R24*Q24 -> 235 | AD24: 0 | AE24: 15.187659 | AF24: 0 | AG24: 0 | AH24: 0 | AI24: 902.58752 | AJ24: 1014.8791 | AK24: =SUM(AD24:AJ24) -> 1932.6543 | AL24: =AK24/F24 -> 0.38653085 | AM24: =F24-AK24 -> 3067.3457
A25: 1.1.15 | B25: Inclusion Sr.Officer (100%) SY | C25: per month | D25: 5 | E25: 650 | F25: =E25*D25 -> 3250 | AD25: 0 | AE25: 0 | AF25: 588.36843 | AG25: 607.02616 | AH25: 622.74934 | AI25: 686.61608 | AJ25: 689.31955 | AK25: =SUM(AD25:AJ25) -> 3194.0795 | AL25: =AK25/F25 -> 0.98279371 | AM25: =F25-AK25 -> 55.92045
A26: 1.1.16 | B26: SNR Officer*1 (100%) - SY | C26: per month | D26: 5 | E26: 500 | F26: =E26*D26 -> 2500 | N26: 1.1.16 | O26: SNR Officer*2 (100%) - SY | P26: per month | Q26: 10 | R26: =E26*$J$3 -> 23.5 | S26: =R26*Q26 -> 235 | U26: =H26*$J$3 -> 0 | V26: =I26*$J$3 -> 0 | W26: =J26*$J$3 -> 0 | X26: =SUM(U26:W26) -> 0 | Y26: =S26-X26 -> 235 | AD26: 0 | AE26: 0 | AF26: 0 | AG26: 217.90066 | AH26: 479.03795 | AI26: 541.55634 | AJ26: 543.68866 | AK26: =SUM(AD26:AJ26) -> 1782.1836 | AL26: =AK26/F26 -> 0.71287344 | AM26: =F26-AK26 -> 717.81639
A27: 1.1.17 | B27: Case Worker*4 (100%) - SY | C27: per month | D27: 20 | E27: 375 | F27: =E27*D27 -> 7500 | N27: 1.1.17 | O27: Case Worker*4 (100%) - SY | P27: per month | Q27: 20 | R27: =E27*$J$3 -> 17.625 | S27: =R27*Q27 -> 352.5 | U27: =H27*$J$3 -> 0 | V27: =I27*$J$3 -> 0 | W27: =J27*$J$3 -> 0 | X27: =SUM(U27:W27) -> 0 | Y27: =S27-X27 -> 352.5 | AD27: 0 | AE27: 456.97358 | AF27: 1024.3526 | AG27: 980.58072 | AH27: 1341.3063 | AI27: 1189.4898 | AJ27: 1205.7373 | AK27: =SUM(AD27:AJ27) -> 6198.4402 | AL27: =AK27/F27 -> 0.8264587 | AM27: =F27-AK27 -> 1301.5598
A28: 1.1.18 | B28: PSS Facilitator*4 (100%) - SY | C28: per month | D28: 20 | E28: 375 | F28: =E28*D28 -> 7500 | N28: 1.1.18 | O28: PSS Facilitator*4 (100%) - SY | P28: per month | Q28: 20 | R28: =E28*$J$3 -> 17.625 | S28: =R28*Q28 -> 352.5 | U28: =H28*$J$3 -> 0 | V28: =I28*$J$3 -> 0 | W28: =J28*$J$3 -> 0 | X28: =SUM(U28:W28) -> 0 | Y28: =S28-X28 -> 352.5 | AD28: 0 | AE28: 0 | AF28: 464.65718 | AG28: 1263.8719 | AH28: 1330.1224 | AI28: 1438.1213 | AJ28: 1196.663 | AK28: =SUM(AD28:AJ28) -> 5693.4357 | AL28: =AK28/F28 -> 0.75912476 | AM28: =F28-AK28 -> 1806.5643
A29: 1.1.19 | B29: Media Officer (100%) - SY | C29: per month | D29: 5 | E29: 500 | F29: =E29*D29 -> 2500 | N29: 1.1.21 | O29: Media Officer (100%) - SY | P29: per month | Q29: 5 | R29: =E29*$J$3 -> 23.5 | S29: =R29*Q29 -> 117.5 | U29: =H29*$J$3 -> 0 | V29: =I29*$J$3 -> 0 | W29: =J29*$J$3 -> 0 | X29: =SUM(U29:W29) -> 0 | Y29: =S29-X29 -> 117.5 | AD29: 0 | AE29: 440.26174 | AF29: 452.5911 | AG29: 466.9432 | AH29: 479.03795 | AI29: 541.55634 | AJ29: 543.68866 | AK29: =SUM(AD29:AJ29) -> 2924.079 | AL29: =AK29/F29 -> 1.1696316 | AM29: =F29-AK29 -> -424.07899
A30: 1.1.21 | B30: Driver (100%) - SY | C30: per month | D30: 5 | E30: 200 | F30: =E30*D30 -> 1000 | N30: 1.1.22 | O30: Receptioinst (100%) - SY | P30: per month | Q30: 5 | R30: =E30*$J$3 -> 9.4 | S30: =R30*Q30 -> 47 | U30: =H30*$J$3 -> 0 | V30: =I30*$J$3 -> 0 | W30: =J30*$J$3 -> 0 | X30: =SUM(U30:W30) -> 0 | Y30: =S30-X30 -> 47 | AD30: 0 | AE30: 0 | AF30: 30.194754 | AG30: 911.7546 | AH30: 191.61518 | AI30: 251.43687 | AJ30: 252.42688 | AK30: =SUM(AD30:AJ30) -> 1637.4283 | AL30: =AK30/F30 -> 1.6374283 | AM30: =F30-AK30 -> -637.42828
A31: 1.1.22 | B31: Cleaner (100%) - SY | C31: per month | D31: 5 | E31: 200 | F31: =E31*D31 -> 1000 | N31: 1.1.24 | O31: Cleaner (100%) - SY | P31: per month | Q31: 5 | R31: =E31*$J$3 -> 9.4 | S31: =R31*Q31 -> 47 | U31: =H31*$J$3 -> 0 | V31: =I31*$J$3 -> 0 | W31: =J31*$J$3 -> 0 | X31: =SUM(U31:W31) -> 0 | Y31: =S31-X31 -> 47 | AD31: 0 | AE31: 0 | AF31: 0 | AG31: 101.16486 | AH31: 239.51898 | AI31: 299.79012 | AJ31: 0 | AK31: =SUM(AD31:AJ31) -> 640.47396 | AL31: =AK31/F31 -> 0.64047396 | AM31: =F31-AK31 -> 359.52604
A32: 1.2 | B32: Honoraires experts | N32: 1.2 | O32: Honoraires experts
A33: 1.2.1 | F33: =E33*D33 -> 0 | H33: =F33 -> 0 | K33: =SUM(H33:J33) -> 0 | L33: =F33-K33 -> 0 | Q33: =$D33 -> 0 | R33: =E33*$J$3 -> 0 | S33: =R33*Q33 -> 0 | U33: =H33*$J$3 -> 0 | V33: =I33*$J$3 -> 0 | W33: =J33*$J$3 -> 0 | X33: =SUM(U33:W33) -> 0 | Y33: =S33-X33 -> 0
F34: =E34*D34 -> 0 | K34: =SUM(H34:J34) -> 0 | L34: =F34-K34 -> 0 | Q34: =$D34 -> 0 | R34: =E34*$J$3 -> 0 | S34: =R34*Q34 -> 0 | U34: =H34*$J$3 -> 0 | V34: =I34*$J$3 -> 0 | W34: =J34*$J$3 -> 0 | X34: =SUM(U34:W34) -> 0 | Y34: =S34-X34 -> 0
A35: 1.3 | B35: Per diem food and accomodation | N35: 1.3 | O35: Per diem food and accomodation
A36: 1.3.1
F37: =E37*D37 -> 0 | K37: =SUM(H37:J37) -> 0 | L37: =F37-K37 -> 0 | Q37: =$D37 -> 0 | R37: =E37*$J$3 -> 0 | S37: =R37*Q37 -> 0 | U37: =H37*$J$3 -> 0 | V37: =I37*$J$3 -> 0 | W37: =J37*$J$3 -> 0 | X37: =SUM(U37:W37) -> 0 | Y37: =S37-X37 -> 0
A38: Sub-total 1 Human resources of the project | F38: =SUM(F9:F37) -> 54000 | H38: =SUM(H10:H37) -> 0 | I38: =SUM(I10:I37) -> 0 | J38: =SUM(J10:J37) -> 0 | K38: =SUM(K10:K37) -> 0 | L38: =SUM(L10:L37) -> 0 | N38: Sub-total 1 Human resources of the project | S38: =SUM(S10:S37) -> 7129.9 | U38: =SUM(U10:U37) -> 0 | V38: =SUM(V10:V37) -> 0 | W38: =SUM(W10:W37) -> 0 | X38: =SUM(X10:X37) -> 0 | Y38: =SUM(Y10:Y37) -> 6894.9 | AA38: =SUM(AA9:AA37) -> 16860
A39: 2 | B39: Travel costs | N39: 2 | O39: Travel costs
A40: 2.1 | B40: 2 Cars for mobile team and benfiaries | C40: per month | D40: 2 | E40: 6000 | H40: 0 | K40: =SUM(H40:J40) -> 0 | L40: =F40-K40 -> 0 | N40: 2.1 | O40: Rental two Cars + running cost (purchase and Running cost) | P40: per month | Q40: =$D40 -> 2 | R40: =E40*$J$3 -> 282 | S40: =R40*Q40 -> 564 | U40: =H40*$J$3 -> 0 | V40: =I40*$J$3 -> 0 | W40: =J40*$J$3 -> 0 | X40: =SUM(U40:W40) -> 0 | Y40: =S40-X40 -> 564 | AA40: =D40*E40*1 -> 12000
...

Sheet Transactions List
A4: No | B4: Budget | C4: REF | D4: no. of vouch-er | E4: Internal voucher number of the Recipient | F4: Date of voucher | G4: Name of the Recipient from voucher/evidence | H4: Reason for payment (detailled content of voucher/evidence) | I4: Currency of voucher | J4: Amount of voucher | K4: Exchange rate (according EU currency converter or exchange of funds) | L4: Expenditure in the currency of Grant Agreement € | N4: Year | O4: Period
A5: 1 | B5: 1.1.08 | C5: S2400800388 | D5: F09683 | E5: Social Security | F5: 45535 | G5: MOHAMMAD YASSER MALATI | H5: MOHAMMAD YASSER MALATI/ Social Security August-2024 / 100% / ( Total Amount 13363.84 ) | I5: TRY | J5: 13363.84 | K5: 0.02792 | L5: =K5*J5 -> 373.11841 | N5: =YEAR(F5) -> 2024 | O5: =MONTH(F5) -> 8 | P5: 0
A6: 2 | B6: 1.1.08 | C6: S2400800388 | D6: F09696 | E6: Income Tax & Stamp | F6: 45535 | G6: MOHAMMAD YASSER MALATI | H6: MOHAMMAD YASSER MALATI/ Income Tax & Stamp Tax August-2024 / 100% / ( Total Amount 4149.53 ) | I6: TRY | J6: 4149.53 | K6: 0.02792 | L6: =K6*J6 -> 115.85488 | N6: =YEAR(F6) -> 2024 | O6: =MONTH(F6) -> 8 | P6: 0
A7: 3 | B7: 1.1.08 | C7: S2400800388 | D7: F09216 | E7: Salary | F7: 45535 | G7: MOHAMMAD YASSER MALATI | H7: MOHAMMAD YASSER MALATI/ Bank Paid Net Salary August-2024 / 100% / ( Total Amount 34113.53 ) | I7: TRY | J7: 24113.53 | K7: 0.02792 | L7: =K7*J7 -> 673.24976 | N7: =YEAR(F7) -> 2024 | O7: =MONTH(F7) -> 8 | P7: 1
A8: 4 | B8: 1.1.08 | C8: S2400900388 | D8: F07182 | E8: Social Security | F8: 45565 | G8: MOHAMMAD YASSER MALATI | H8: MOHAMMAD YASSER MALATI/ Social Security September-2024 / 100% / ( Total Amount 13466.64 ) | I8: TRY | J8: 13466.64 | K8: 0.02646 | L8: =K8*J8 -> 356.32729 | N8: =YEAR(F8) -> 2024 | O8: =MONTH(F8) -> 9 | P8: 0
A9: 5 | B9: 1.1.08 | C9: S2400900388 | D9: F08575 | E9: Salary | F9: 45565 | G9: MOHAMMAD YASSER MALATI | H9: MOHAMMAD YASSER MALATI/ Bank Paid Net Salary September-2024 / 100% / ( Total Amount 32702.31 ) | I9: TRY | J9: 32702.31 | K9: 0.02646 | L9: =K9*J9 -> 865.30312 | N9: =YEAR(F9) -> 2024 | O9: =MONTH(F9) -> 9 | P9: 0
A10: 6 | B10: 1.1.08 | C10: S2400900388 | D10: F05725 | E10: Income Tax & Stamp | F10: 45565 | G10: MOHAMMAD YASSER MALATI | H10: MOHAMMAD YASSER MALATI/ Income Tax & Stamp Tax September-2024 / 100% / ( Total Amount 5560.76 ) | I10: TRY | J10: 5560.76 | K10: 0.02646 | L10: =K10*J10 -> 147.13771 | N10: =YEAR(F10) -> 2024 | O10: =MONTH(F10) -> 9 | P10: 0
A11: 7 | B11: 1.1.08 | C11: S2400900388 | D11: F07098 | E11: SGK Discount | F11: 45581 | G11: MOHAMMAD YASSER MALATI | H11: MOHAMMAD YASSER MALATI/ SGK Discount September-2024 / 100% / ( Total Amount 55.72 ) | I11: TRY | J11: -55.72 | K11: 0.02622 | L11: =K11*J11 -> -1.4609784 | N11: =YEAR(F11) -> 2024 | O11: =MONTH(F11) -> 10 | P11: 0
A12: 8 | B12: 1.1.08 | C12: S2401000388 | D12: F07075 | E12: Social Security | F12: 45596 | G12: MOHAMMAD YASSER MALATI | H12: MOHAMMAD YASSER MALATI/ Social Security October-2024 / 100% / ( Total Amount 13415 ) | I12: TRY | J12: 13415 | K12: 0.02622 | L12: =K12*J12 -> 351.7413 | N12: =YEAR(F12) -> 2024 | O12: =MONTH(F12) -> 10 | P12: 0
A13: 9 | B13: 1.1.08 | C13: S2401000388 | D13: F06413 | E13: Income Tax & Stamp | F13: 45596 | G13: MOHAMMAD YASSER MALATI | H13: MOHAMMAD YASSER MALATI/ Income Tax & Stamp Tax October-2024 / 100% / ( Total Amount 6159.4 ) | I13: TRY | J13: 6159.4 | K13: 0.02622 | L13: =K13*J13 -> 161.49947 | N13: =YEAR(F13) -> 2024 | O13: =MONTH(F13) -> 10 | P13: 0
A14: 10 | B14: 1.1.08 | C14: S2401000388 | D14: F09894 | E14: Salary | F14: 45596 | G14: MOHAMMAD YASSER MALATI | H14: MOHAMMAD YASSER MALATI/ Bank Paid Net Salary October-2024 / 100% / ( Total Amount 32127.33 ) | I14: TRY | J14: 32127.33 | K14: 0.02622 | L14: =K14*J14 -> 842.37859 | N14: =YEAR(F14) -> 2024 | O14: =MONTH(F14) -> 10 | P14: 0
A15: 11 | B15: 1.1.08 | C15: S2401000388 | D15: F07075 | E15: SGK Discount | F15: 45616 | G15: MOHAMMAD YASSER MALATI | H15: MOHAMMAD YASSER MALATI/ SGK Discount October-2024 / 100% / ( Total Amount 60.6 ) | I15: TRY | J15: -60.6 | K15: 0.02696 | L15: =K15*J15 -> -1.633776 | N15: =YEAR(F15) -> 2024 | O15: =MONTH(F15) -> 11 | P15: 0
A16: 12 | B16: 1.1.08 | C16: S2401100388 | D16: F12225 | E16: Income Tax & Stamp | F16: 45626 | G16: MOHAMMAD YASSER MALATI | H16: MOHAMMAD YASSER MALATI/ Income Tax & Stamp Tax November-2024 / 100% / ( Total Amount 6196.79 ) | I16: TRY | J16: 6196.79 | K16: 0.02696 | L16: =K16*J16 -> 167.06546 | N16: =YEAR(F16) -> 2024 | O16: =MONTH(F16) -> 11 | P16: 0
... A145: 141 | B145: 1.1.21 | C145: S2411000434 | D145: PTT | E145: PTT USD | F145: 45596 | G145: PTT- USD | H145: Commission fees / ABDULHAMID JUMA / Driver / Salary of October-2024 Net Salary Paid by Bank for 5 days / 33.33 USD | I145: USD | J145: 0.3333 | K145: 0.89622 | L145: =K145*J145 -> 0.29871013 | N145: =YEAR(F145) -> 2024 | O145: =MONTH(F145) -> 10 | P145: 0
A146: 142 | B146: 1.1.21 | C146: S2411000623 | D146: PTT | E146: 9502 | F146: 45597 | G146: AZIZ AL AZO-USD | H146: 2 Days fees for driver / dayson 23rd & 24th October 2024 / for a temporary position spanning two working / 30.00 USD x34.2011= 1026.033 Indicative Exchange Rates Announced at 15:30 on 23/10/2024by the Central Bank of Turkey / for -Oct-2024 30.00 USD/DPR1104558734/ Invoice#09502 | I146: TRY | J146: 26 | K146: 0.02696 | L146: =K146*J146 -> 0.70096 | N146: =YEAR(F146) -> 2024 | O146: =MONTH(F146) -> 11 | P146: 1
A147: 143 | B147: 1.1.21 | C147: S2411000635 | D147: PTT | E147: PTT USD | F147: 45624 | G147: PTT- USD | H147: Commission fees / ABDULHAMID JUMA / Driver / Salary of November-2024 Net Salary Paid by Bank / 200 USD | I147: USD | J147: 2 | K147: 0.92464 | L147: =K147*J147 -> 1.84928 | N147: =YEAR(F147) -> 2024 | O147: =MONTH(F147) -> 11 | P147: 0
A148: 144 | B148: 1.1.21 | C148: S2401100194 | D148: PTT | E148: Income Tax & Stamp | F148: 45626 | G148: FIRAS HAJ ISSA | H148: FIRAS HAJ ISSA/ Income Tax & Stamp Tax November-2024 / 100% / ( Total Amount 6196.79 ) 50% | I148: TRY | J148: 3098.39 | K148: 0.02696 | L148: =K148*J148 -> 83.532594 | N148: =YEAR(F148) -> 2024 | O148: =MONTH(F148) -> 11 | P148: 0
A149: 145 | B149: 1.1.21 | C149: S2401100468 | D149: PTT | E149: Salary | F149: 45626 | G149: ABDULHAMID JUMA USD | H149: ABDULHAMID JUMA / Driver / Salary of November-2024 Net Salary Paid by Bank / 200 USD | I149: USD | J149: 200 | K149: 0.92464 | L149: =K149*J149 -> 184.928 | N149: =YEAR(F149) -> 2024 | O149: =MONTH(F149) -> 11 | P149: 0
A150: 146 | B150: 1.1.21 | C150: S2401100194 | D150: PTT | E150: Salary | F150: 45626 | G150: FIRAS HAJ ISSA | H150: FIRAS HAJ ISSA/ Bank Paid Net Salary November-2024 / 100% / ( Total Amount 32066.28 ) 50% | I150: TRY | J150: 16033.14 | K150: 0.02696 | L150: =K150*J150 -> 432.25345 | N150: =YEAR(F150) -> 2024 | O150: =MONTH(F150) -> 11 | P150: 0
A151: 147 | B151: 1.1.21 | C151: S2401100194 | D151: PTT | E151: Social Security | F151: 45626 | G151: FIRAS HAJ ISSA | H151: FIRAS HAJ ISSA/ Social Security November-2024 / 100% / ( Total Amount 13466.64 ) 50% | I151: TRY | J151: 6733.32 | K151: 0.02696 | L151: =K151*J151 -> 181.53031 | N151: =YEAR(F151) -> 2024 | O151: =MONTH(F151) -> 11 | P151: 0
A152: 148 | B152: 1.1.21 | C152: S2411000659 | D152: PTT | E152: Commission fees | F152: 45652 | G152: PTT- USD | H152: 1% PTT Fees of ABDULHAMID JUMA / Driver / Salary of December-2024 Net Salary Paid by Bank / 200 USD | I152: USD | J152: 2 | K152: 0.94859 | L152: =K152*J152 -> 1.89718 | N152: =YEAR(F152) -> 2024 | O152: =MONTH(F152) -> 12 | P152: 0
A153: 149 | B153: 1.1.21 | C153: S2401200468 | D153: PTT | E153: Salary | F153: 45652 | G153: ABDULHAMID JUMA USD | H153: ABDULHAMID JUMA / Driver / Salary of December-2024 Net Salary Paid by Bank / 200 USD | I153: USD | J153: 200 | K153: 0.94859 | L153: =K153*J153 -> 189.718 | N153: =YEAR(F153) -> 2024 | O153: =MONTH(F153) -> 12 | P153: 0
A154: 150 | B154: 1.1.22 | C154: S2411000635 | D154: PTT | E154: PTT USD | F154: 45624 | G154: PTT- USD | H154: Commission fees / MUNTAZER NASIF / Cleaner / Salary of November-2024 Net Salary Paid by Bank for 13 days / 108.33 USD | I154: USD | J154: 1.08 | K154: 0.92464 | L154: =K154*J154 -> 0.9986112 | N154: =YEAR(F154) -> 2024 | O154: =MONTH(F154) -> 11 | P154: 0
A155: 151 | B155: 1.1.22 | C155: S2401100474 | D155: PTT | E155: Salary | F155: 45626 | G155: MUNTAZER NASIF USD | H155: MUNTAZER NASIF / Cleaner / Salary of November-2024 Net Salary Paid by Bank for 13 days / 108.33 USD | I155: USD | J155: 108.33 | K155: 0.92464 | L155: =K155*J155 -> 100.16625 | N155: =YEAR(F155) -> 2024 | O155: =MONTH(F155) -> 11 | P155: 0
A156: 152 | B156: 1.1.22 | C156: S2401200474 | D156: PTT | E156: Salary | F156: 45652 | G156: MUNTAZER NASIF USD | H156: MUNTAZER NASIF / Cleaner / Salary of December-2024 Net Salary Paid by Bank / 250 USD | I156: USD | J156: 250 | K156: 0.94859 | L156: =K156*J156 -> 237.1475 | N156: =YEAR(F156) -> 2024 | O156: =MONTH(F156) -> 12 | P156: 0
A157: 153 | B157: 1.1.22 | C157: S2411000659 | D157: PTT | E157: Commission fees | F157: 45652 | G157: PTT- USD | H157: 1% PTT Fees of MUNTAZER NASIF / Cleaner / Salary of December-2024 Net Salary Paid by Bank / 250 USD | I157: USD | J157: 2.5 | K157: 0.94859 | L157: =K157*J157 -> 2.371475 | N157: =YEAR(F157) -> 2024 | O157: =MONTH(F157) -> 12 | P157: 0
A158: 154 | B158: 2.2 | C158: S2417100007 | D158: 112 | E158: 26263 | F158: 45536 | G158: ABDO AL ASSEAD (PORRIDGE FOR FUEL)-USD | H158: 80 Liters / Fuel Filling for Cm /80* 0,90USD /+ Car Wash Cm/ DPR1714560778 / Invoice#026263 | I158: USD | J158: 75 | K158: 0.90188 | L158: =K158*J158 -> 67.641 | N158: =YEAR(F158) -> 2024 | O158: =MONTH(F158) -> 9 | P158: 0
A159: 155 | B159: 2.2 | C159: S2417100004 | D159: 113 | E159: 26267 | F159: 45542 | G159: ABDO AL ASSEAD (PORRIDGE FOR FUEL)-USD | H159: 70 Liters / Fuel Filling for H1 /70 * 0,9 / + Car Wash Cm + Car Wash H1/ DPR1714560772 /Invoice#026267 | I159: USD | J159: 71 | K159: 0.90188 | L159: =K159*J159 -> 64.03348 | N159: =YEAR(F159) -> 2024 | O159: =MONTH(F159) -> 9 | P159: 0
A160: 156 | B160: 2.2 | C160: S2417100005 | D160: 114 | E160: 26273 | F160: 45566 | G160: ABDO AL ASSEAD (PORRIDGE FOR FUEL)-USD | H160: 41 Liters / Fuel Filling for H1 / 41* 0,9 USD / + Car Wash Cm + Car Wash H1 / DPR1714560737 / Invoice#026273 | I160: USD | J160: 44.9 | K160: 0.89622 | L160: =K160*J160 -> 40.240278 | N160: =YEAR(F160) -> 2024 | O160: =MONTH(F160) -> 10 | P160: 0
A161: 157 | B161: 2.2 | C161: S2417100006 | D161: 115 | E161: 751 | F161: 45567 | G161: MOHAMAD DIAB MALDOAN-USD | H161: 35 Liters / Filling fuel for a cm car /35 L* 0,9 USD / + replacing the cm battery / DPR1714560798 /Invoice#0751 | I161: USD | J161: 96.5 | K161: 0.89622 | L161: =K161*J161 -> 86.48523 | N161: =YEAR(F161) -> 2024 | O161: =MONTH(F161) -> 10 | P161: 0
A162: 158 | B162: 2.2 | C162: S2417100009 | D162: 117 | E162: 3156 | F162: 45599 | G162: MOHAMAD DIAB MALDOAN-USD | H162: 72 Liters / Fuel Filling for H1/ DPR1714561970 / Invoice#3156 | I162: TRY | J162: 2772 | K162: 0.02696 | L162: =K162*J162 -> 74.73312 | N162: =YEAR(F162) -> 2024 | O162: =MONTH(F162) -> 11 | P162: 0
A163: 159 | B163: 2.2 | C163: S2417100010 | D163: 120 | E163: 3154 | F163: 45619 | G163: MOHAMAD DIAB MALDOAN-USD | H163: Engine oil change cm, h1 + transmission oil change cm, h1 / 99.00USD x34.4642 = 3412.00 Indicative Exchange Rates Announced at 15:30 on 22/11/2024by the Central Bank of Turkey / for -Nov-2024 99 USD / DPR17145620100 / Invoice#3154 | I163: TRY | J163: 3412 | K163: 0.02696 | L163: =K163*J163 -> 91.98752 | N163: =YEAR(F163) -> 2024 | O163: =MONTH(F163) -> 11 | P163: 0
A164: 160 | B164: 2.2 | C164: S2417100011 | D164: 139 | E164: 3157 | F164: 45627 | G164: MOHAMAD DIAB MALDOAN-USD | H164: Fuel Filling for H1+ Car Wash H1. Invoice#3157 | I164: TRY | J164: 3060 | K164: 0.02741 | L164: =K164*J164 -> 83.8746 | N164: =YEAR(F164) -> 2024 | O164: =MONTH(F164) -> 12 | P164: 0
A165: 161 | B165: 2.2 | C165: S2417100013 | D165: 153 | E165: 36 | F165: 45643 | G165: ABDULLAH DEK ( ALDEK TRADING COMPANY)-USD | H165: 79 Liters Diesel / 79*39 TRY / Fuel Filling for H1 / INV#0036 | I165: TRY | J165: 3120 | K165: 0.02741 | L165: =K165*J165 -> 85.5192 | N165: =YEAR(F165) -> 2024 | O165: =MONTH(F165) -> 12 | P165: 0
A166: 162 | B166: 2.2 | C166: S2417100014 | D166: 3169 | E166: 3169 | F166: 45650 | G166: MOHAMAD DIAB MALDOAN-USD | H166: 4 cm high quality Cm car wheels.Invoice#3169 | I166: TRY | J166: 13165 | K166: 0.02741 | L166: =K166*J166 -> 360.85265 | N166: =YEAR(F166) -> 2024 | O166: =MONTH(F166) -> 12 | P166: 0
A167: 163 | B167: 3.1.10 | C167: S2417100002 | D167: PTT | E167: 5601 | F167: 45617 | G167: Sham AD.Agency -ABDULMNUM JAWOUYSH- USD | H167: Supplies Materials / Distribute to Beneficiaries / Roll up size 85 * 200 cm + Single side, A5 color Brochures printing + Poster + white wooden box designed for complaints + Regular card cardboard + PSEA Poster + A4 Brochures + PSEA Poster Adult + PSEA A4 Brochures + Table flags + Wall flags /PR#24-SYR-AZA-537 /INV#005601 | I167: USD | J167: 2790.8 | K167: 0.92464 | L167: =K167*J167 -> 2580.4853 | N167: =YEAR(F167) -> 2024 | O167: =MONTH(F167) -> 11 | P167: 1
A168: 164 | B168: 3.1.10 | C168: S2411000635 | D168: PTT | E168: PTT USD | F168: 45624 | G168: PTT- USD | H168: Commission fees / Supplies Materials / Distribute to Beneficiaries / Roll up size 85 * 200 cm + Single side, A5 color Brochures printing + Poster + white wooden box designed for complaints + Regular card cardboard + PSEA Poster + A4 Brochures + PSEA Poster Adult + PSEA A4 Brochures + Table flags + Wall flags /PR#24-SYR-AZA-537 /INV#005601 | I168: USD | J168: 2.798 | K168: 0.92464 | L168: =K168*J168 -> 2.5871427 | N168: =YEAR(F168) -> 2024 | O168: =MONTH(F168) -> 11 | P168: 0
A169: 165 | B169: 3.1.10 | C169: S2411000632 | D169: PTT | E169: 1681 | F169: 45627 | G169: ALI AL SED ALI ( TAYBA TRADING) USD | H169: 25 Vests / for Sened Organization employees in A'zaz and Idlib regions / northwest Syria + carrying / the new Sened Organization logo /PR#24-SYR-AZA-560/INV#1681 | I169: USD | J169: 210 | K169: 0.94859 | L169: =K169*J169 -> 199.2039 | N169: =YEAR(F169) -> 2024 | O169: =MONTH(F169) -> 12 | P169: 0
A170: 166 | B170: 3.1.11 | C170: S2417100003 | D170: PTT | E170: 1682 + 1683 + 1684 + 1685 | F170: 45608 | G170: ALI AL SED ALI ( TAYBA TRADING) USD | H170: One Set Montessori Tools and Materials for Project Activities / including 96 items / PR#24-SYR-AZA-535 /INVS# 1682 + 1683 + 1684 + 1685 | I170: USD | J170: 559.65 | K170: 0.92464 | L170: =K170*J170 -> 517.47478 | N170: =YEAR(F170) -> 2024 | O170: =MONTH(F170) -> 11 | P170: 0
A171: 167 | B171: 3.1.11 | C171: S2411000635 | D171: PTT | E171: PTT USD | F171: 45624 | G171: PTT- USD | H171: Commission fees / One Set Montessori Tools and Materials for Project Activities / including 96 items / PR#24-SYR-AZA-535 /INVS# 1682 + 1683 + 1684 + 1685 | I171: USD | J171: 5.5965 | K171: 0.92464 | L171: =K171*J171 -> 5.1747478 | N171: =YEAR(F171) -> 2024 | O171: =MONTH(F171) -> 11 | P171: 0
...

Sheet Project Budget in euros
A1: !!Please insert lines under the sub-headings if necessary!! !! Pay attention not to erase formulas in the blue cells !! | L1: Please check the totals in each column per year and the total in column G (Difference = 0)
A2: Name of the person in charge of the budget:
A3: Name of the applicant organisation:
A4: Project title:
B5: Instructions for filling in the Expenses column | C5: Expenditure related to the project | D5: Unit | E5: Number of units | F5: Unit cost (in €) | G5: Total cost (in €) | I5: Year 1 | J5: Year 2 | K5: Year 3 | L5: Total (I to K) for control purposes | M5: Discrepancy (with G column)
A6: 1 | C6: Human resources dedicated to the project
A7: 1.1 | C7: Salaries and employer's contributions
A8: 1.1.1 | B8: Indicate the staff position concerned | D8: per month | G8: =F8*E8 -> 0 | L8: =SUM(I8:K8) -> 0 | M8: =L8-G8 -> 0
A9: 1.1.2 | B9: Indicate the staff position concerned | D9: per month | G9: =F9*E9 -> 0 | L9: =SUM(I9:K9) -> 0 | M9: =L9-G9 -> 0
A10: 1.2 | C10: Expert's fees
A11: 1.2.1 | B11: Function of the expert | D11: per day | G11: =F11*E11 -> 0 | L11: =SUM(I11:K11) -> 0 | M11: =L11-G11 -> 0
A12: 1.2.2 | B12: Function of the expert | D12: per day | G12: =F12*E12 -> 0 | L12: =SUM(I12:K12) -> 0 | M12: =L12-G12 -> 0
A13: 1.3 | C13: Per diem food and accommodation costs
A14: 1.3.1 | B14: Purpose of the per diem expenditure | D14: per day | G14: =F14*E14 -> 0 | L14: =SUM(I14:K14) -> 0 | M14: =L14-G14 -> 0
A15: 1.3.2 | B15: Purpose of the per diem expenditure | D15: per day | G15: =F15*E15 -> 0 | L15: =SUM(I15:K15) -> 0 | M15: =L15-G15 -> 0
A16: Sub-total 1 Human resources for the project | G16: =SUM(G8:G15) -> 0 | I16: =SUM(I8:I15) -> 0 | J16: =SUM(J8:J15) -> 0 | K16: =SUM(K8:K15) -> 0 | L16: =SUM(I16:K16) -> 0 | M16: =L16-G16 -> 0
A17: 2 | C17: Travel
A18: 2.1 | B18: Purpose of the journey | D18: per trip | G18: =F18*E18 -> 0 | L18: =SUM(I18:K18) -> 0 | M18: =L18-G18 -> 0
A19: 2.2 | B19: Purpose of the journey | D19: per trip | G19: =F19*E19 -> 0 | L19: =SUM(I19:K19) -> 0 | M19: =L19-G19 -> 0
A20: Sub-total 2 Travel required for the project | G20: =SUM(G19,G18) -> 0 | I20: =SUM(I19,I18) -> 0 | J20: =SUM(J19,J18) -> 0 | K20: =SUM(K19,K18) -> 0 | L20: =SUM(I20:K20) -> 0 | M20: =L20-G20 -> 0
A21: 3 | C21: Equipment and supplies
A22: 3.1.1 | B22: Expenditure on equipment for the project | G22: =F22*E22 -> 0 | L22: =SUM(I22:K22) -> 0 | M22: =L22-G22 -> 0
A23: 3.1.2 | B23: Expenditure on equipment for the project | G23: =F23*E23 -> 0 | L23: =SUM(I23:K23) -> 0 | M23: =L23-G23 -> 0
A24: 3.2.1 | B24: Expenditure on equipment for the project | G24: =F24*E24 -> 0 | L24: =SUM(I24:K24) -> 0 | M24: =L24-G24 -> 0
A25: 3.2.2 | B25: Expenditure on equipment for the project | G25: =F25*E25 -> 0 | L25: =SUM(I25:K25) -> 0 | M25: =L25-G25 -> 0
A26: Sub-total 3 Equipment and supplies | G26: =SUM(G22:G25) -> 0 | I26: =SUM(I22:I25) -> 0 | J26: =SUM(J22:J25) -> 0 | K26: =SUM(K22:K25) -> 0 | L26: =SUM(I26:K26) -> 0 | M26: =L26-G26 -> 0
A27: 4 | C27: Other expenses
A28: 4.1 | B28: Type of expense (e.g. printing costs) | D28: per document | G28: =F28*E28 -> 0 | L28: =SUM(I28:K28) -> 0 | M28: =L28-G28 -> 0
A29: 4.2 | B29: Type of expense (e.g. rental of premises) | D29: per day | G29: =F29*E29 -> 0 | L29: =SUM(I29:K29) -> 0 | M29: =L29-G29 -> 0
A30: 4.3 | B30: Other expenses | G30: =F30*E30 -> 0 | L30: =SUM(I30:K30) -> 0 | M30: =L30-G30 -> 0
A31: 4.4 | G31: =F31*E31 -> 0 | L31: =SUM(I31:K31) -> 0 | M31: =L31-G31 -> 0
A32: 4.5 | G32: =F32*E32 -> 0 | L32: =SUM(I32:K32) -> 0 | M32: =L32-G32 -> 0
A33: Sub-total 4 Other expenses | G33: =SUM(G28:G32) -> 0 | I33: =SUM(I28:I32) -> 0 | J33: =SUM(J28:J32) -> 0 | K33: =SUM(K28:K32) -> 0 | L33: =SUM(I33:K33) -> 0 | M33: =L33-G33 -> 0
A34: Sub-total 5 Administrative costs | G34: =(G16+G20+G26+G33)*10% -> 0 | I34: =(I16+I20+I26+I33)*10% -> 0 | J34: =(J16+J20+J26+J33)*10% -> 0 | K34: =(K16+K20+K26+K33)*10% -> 0 | L34: =SUM(I34:K34) -> 0 | M34: =L34-G34 -> 0
A35: TOTAL DIRECT COST OF THE PROJECT (1 to 5) | G35: =SUM(G34,G33,G26,G20,G16) -> 0 | I35: =SUM(I34,I33,I26,I20,I16) -> 0 | J35: =SUM(J34,J33,J26,J20,J16) -> 0 | K35: =SUM(K34,K33,K26,K20,K16) -> 0 | L35: =SUM(I35:K35) -> 0 | M35: =L35-G35 -> 0
A37: FINANCING PLAN | D37: Requested | E37: Raised | F37: Percentage | G37: in € | I37: in € | J37: in € | K37: in € | L37: in € | M37: in €
A38: Grant requested (maximum 80% of the project) | F38: =G38/$G$45 -> #DIV/0! | L38: =SUM(I38:K38) -> 0 | M38: =L38-G38 -> 0
A39: Other donors (name) | F39: =G39/$G$45 -> #DIV/0! | L39: =SUM(I39:K39) -> 0 | M39: =L39-G39 -> 0
A40: Other donors (name) | F40: =G40/$G$45 -> #DIV/0! | L40: =SUM(I40:K40) -> 0 | M40: =L40-G40 -> 0
A41: Other donors (name) | F41: =G41/$G$45 -> #DIV/0! | L41: =SUM(I41:K41) -> 0 | M41: =L41-G41 -> 0
...
